Workbook

Sheet Plan del Día
A1: PLAN DEL DÍA | B1: Fecha / Date: | F1: Total personas / people: | G1: =B13+D13+F13+H13+J13+L13+N13+P13 -> 0 | I1: Nombres repetidos / Repeated: | J1: =SUMPRODUCT(($AN$6:$AU$64<>"")*(COUNTIF($AN$6:$AU$64,$AN$6:$AU$64)>1)) -> 0
A2: Escribe solo en las celdas crema. Un bloque (2 columnas) por proyecto. Cada persona en su fila con su responsabilidad al lado; responsabilidad en blanco = la misma de arriba.
A3: Proyecto / Project
A4: Sitio / Site
A5: Horario: inicio | fin
A6: Líder / Lead | AN6: =IF(B6="","",TRIM(IFERROR(LEFT(B6,FIND("(",B6)-1),B6))) | AO6: =IF(D6="","",TRIM(IFERROR(LEFT(D6,FIND("(",D6)-1),D6))) | AP6: =IF(F6="","",TRIM(IFERROR(LEFT(F6,FIND("(",F6)-1),F6))) | AQ6: =IF(H6="","",TRIM(IFERROR(LEFT(H6,FIND("(",H6)-1),H6))) | AR6: =IF(J6="","",TRIM(IFERROR(LEFT(J6,FIND("(",J6)-1),J6))) | AS6: =IF(L6="","",TRIM(IFERROR(LEFT(L6,FIND("(",L6)-1),L6))) | AT6: =IF(N6="","",TRIM(IFERROR(LEFT(N6,FIND("(",N6)-1),N6))) | AU6: =IF(P6="","",TRIM(IFERROR(LEFT(P6,FIND("(",P6)-1),P6)))
A7: Contratista 1: nombre | cuántos
A8: Contratista 1: inicio | fin
A9: Contratista 2: nombre | cuántos
A10: Contratista 2: inicio | fin
A11: Notas / Notes
A12: Nombrados (incl. líder) | B12: =(B6<>"")+COUNTA(C15:C64) -> 0 | D12: =(D6<>"")+COUNTA(E15:E64) -> 0 | F12: =(F6<>"")+COUNTA(G15:G64) -> 0 | H12: =(H6<>"")+COUNTA(I15:I64) -> 0 | J12: =(J6<>"")+COUNTA(K15:K64) -> 0 | L12: =(L6<>"")+COUNTA(M15:M64) -> 0 | N12: =(N6<>"")+COUNTA(O15:O64) -> 0 | P12: =(P6<>"")+COUNTA(Q15:Q64) -> 0
A13: TOTAL (con contratistas) | B13: =B12+N(C7)+N(C9) -> 0 | D13: =D12+N(E7)+N(E9) -> 0 | F13: =F12+N(G7)+N(G9) -> 0 | H13: =H12+N(I7)+N(I9) -> 0 | J13: =J12+N(K7)+N(K9) -> 0 | L13: =L12+N(M7)+N(M9) -> 0 | N13: =N12+N(O7)+N(O9) -> 0 | P13: =P12+N(Q7)+N(Q9) -> 0
A14: Responsabilidad | Nombre ↓ | B14: Responsabilidad | C14: Nombre | D14: Responsabilidad | E14: Nombre | F14: Responsabilidad | G14: Nombre | H14: Responsabilidad | I14: Nombre | J14: Responsabilidad | K14: Nombre | L14: Responsabilidad | M14: Nombre | N14: Responsabilidad | O14: Nombre | P14: Responsabilidad | Q14: Nombre
A15: 1 | T15: =IF(B15<>"",TRIM(IFERROR(LEFT(B15,FIND("(",B15)-1),B15)),"") | U15: =IF(D15<>"",TRIM(IFERROR(LEFT(D15,FIND("(",D15)-1),D15)),"") | V15: =IF(F15<>"",TRIM(IFERROR(LEFT(F15,FIND("(",F15)-1),F15)),"") | W15: =IF(H15<>"",TRIM(IFERROR(LEFT(H15,FIND("(",H15)-1),H15)),"") | X15: =IF(J15<>"",TRIM(IFERROR(LEFT(J15,FIND("(",J15)-1),J15)),"") | Y15: =IF(L15<>"",TRIM(IFERROR(LEFT(L15,FIND("(",L15)-1),L15)),"") | Z15: =IF(N15<>"",TRIM(IFERROR(LEFT(N15,FIND("(",N15)-1),N15)),"") | AA15: =IF(P15<>"",TRIM(IFERROR(LEFT(P15,FIND("(",P15)-1),P15)),"") | AD15: =IF(C15="","",IF(T15="","(sin responsabilidad)",T15)) | AE15: =IF(E15="","",IF(U15="","(sin responsabilidad)",U15)) | AF15: =IF(G15="","",IF(V15="","(sin responsabilidad)",V15)) | AG15: =IF(I15="","",IF(W15="","(sin responsabilidad)",W15)) | AH15: =IF(K15="","",IF(X15="","(sin responsabilidad)",X15)) | AI15: =IF(M15="","",IF(Y15="","(sin responsabilidad)",Y15)) | AJ15: =IF(O15="","",IF(Z15="","(sin responsabilidad)",Z15)) | AK15: =IF(Q15="","",IF(AA15="","(sin responsabilidad)",AA15)) | AN15: =IF(C15="","",TRIM(IFERROR(LEFT(C15,FIND("(",C15)-1),C15))) | AO15: =IF(E15="","",TRIM(IFERROR(LEFT(E15,FIND("(",E15)-1),E15))) | AP15: =IF(G15="","",TRIM(IFERROR(LEFT(G15,FIND("(",G15)-1),G15))) | AQ15: =IF(I15="","",TRIM(IFERROR(LEFT(I15,FIND("(",I15)-1),I15))) | AR15: =IF(K15="","",TRIM(IFERROR(LEFT(K15,FIND("(",K15)-1),K15))) | AS15: =IF(M15="","",TRIM(IFERROR(LEFT(M15,FIND("(",M15)-1),M15))) | AT15: =IF(O15="","",TRIM(IFERROR(LEFT(O15,FIND("(",O15)-1),O15))) | AU15: =IF(Q15="","",TRIM(IFERROR(LEFT(Q15,FIND("(",Q15)-1),Q15)))
A16: 2 | T16: =IF(B16<>"",TRIM(IFERROR(LEFT(B16,FIND("(",B16)-1),B16)),T15) | U16: =IF(D16<>"",TRIM(IFERROR(LEFT(D16,FIND("(",D16)-1),D16)),U15) | V16: =IF(F16<>"",TRIM(IFERROR(LEFT(F16,FIND("(",F16)-1),F16)),V15) | W16: =IF(H16<>"",TRIM(IFERROR(LEFT(H16,FIND("(",H16)-1),H16)),W15) | X16: =IF(J16<>"",TRIM(IFERROR(LEFT(J16,FIND("(",J16)-1),J16)),X15) | Y16: =IF(L16<>"",TRIM(IFERROR(LEFT(L16,FIND("(",L16)-1),L16)),Y15) | Z16: =IF(N16<>"",TRIM(IFERROR(LEFT(N16,FIND("(",N16)-1),N16)),Z15) | AA16: =IF(P16<>"",TRIM(IFERROR(LEFT(P16,FIND("(",P16)-1),P16)),AA15) | AD16: =IF(C16="","",IF(T16="","(sin responsabilidad)",T16)) | AE16: =IF(E16="","",IF(U16="","(sin responsabilidad)",U16)) | AF16: =IF(G16="","",IF(V16="","(sin responsabilidad)",V16)) | AG16: =IF(I16="","",IF(W16="","(sin responsabilidad)",W16)) | AH16: =IF(K16="","",IF(X16="","(sin responsabilidad)",X16)) | AI16: =IF(M16="","",IF(Y16="","(sin responsabilidad)",Y16)) | AJ16: =IF(O16="","",IF(Z16="","(sin responsabilidad)",Z16)) | AK16: =IF(Q16="","",IF(AA16="","(sin responsabilidad)",AA16)) | AN16: =IF(C16="","",TRIM(IFERROR(LEFT(C16,FIND("(",C16)-1),C16))) | AO16: =IF(E16="","",TRIM(IFERROR(LEFT(E16,FIND("(",E16)-1),E16))) | AP16: =IF(G16="","",TRIM(IFERROR(LEFT(G16,FIND("(",G16)-1),G16))) | AQ16: =IF(I16="","",TRIM(IFERROR(LEFT(I16,FIND("(",I16)-1),I16))) | AR16: =IF(K16="","",TRIM(IFERROR(LEFT(K16,FIND("(",K16)-1),K16))) | AS16: =IF(M16="","",TRIM(IFERROR(LEFT(M16,FIND("(",M16)-1),M16))) | AT16: =IF(O16="","",TRIM(IFERROR(LEFT(O16,FIND("(",O16)-1),O16))) | AU16: =IF(Q16="","",TRIM(IFERROR(LEFT(Q16,FIND("(",Q16)-1),Q16)))
A17: 3 | T17: =IF(B17<>"",TRIM(IFERROR(LEFT(B17,FIND("(",B17)-1),B17)),T16) | U17: =IF(D17<>"",TRIM(IFERROR(LEFT(D17,FIND("(",D17)-1),D17)),U16) | V17: =IF(F17<>"",TRIM(IFERROR(LEFT(F17,FIND("(",F17)-1),F17)),V16) | W17: =IF(H17<>"",TRIM(IFERROR(LEFT(H17,FIND("(",H17)-1),H17)),W16) | X17: =IF(J17<>"",TRIM(IFERROR(LEFT(J17,FIND("(",J17)-1),J17)),X16) | Y17: =IF(L17<>"",TRIM(IFERROR(LEFT(L17,FIND("(",L17)-1),L17)),Y16) | Z17: =IF(N17<>"",TRIM(IFERROR(LEFT(N17,FIND("(",N17)-1),N17)),Z16) | AA17: =IF(P17<>"",TRIM(IFERROR(LEFT(P17,FIND("(",P17)-1),P17)),AA16) | AD17: =IF(C17="","",IF(T17="","(sin responsabilidad)",T17)) | AE17: =IF(E17="","",IF(U17="","(sin responsabilidad)",U17)) | AF17: =IF(G17="","",IF(V17="","(sin responsabilidad)",V17)) | AG17: =IF(I17="","",IF(W17="","(sin responsabilidad)",W17)) | AH17: =IF(K17="","",IF(X17="","(sin responsabilidad)",X17)) | AI17: =IF(M17="","",IF(Y17="","(sin responsabilidad)",Y17)) | AJ17: =IF(O17="","",IF(Z17="","(sin responsabilidad)",Z17)) | AK17: =IF(Q17="","",IF(AA17="","(sin responsabilidad)",AA17)) | AN17: =IF(C17="","",TRIM(IFERROR(LEFT(C17,FIND("(",C17)-1),C17))) | AO17: =IF(E17="","",TRIM(IFERROR(LEFT(E17,FIND("(",E17)-1),E17))) | AP17: =IF(G17="","",TRIM(IFERROR(LEFT(G17,FIND("(",G17)-1),G17))) | AQ17: =IF(I17="","",TRIM(IFERROR(LEFT(I17,FIND("(",I17)-1),I17))) | AR17: =IF(K17="","",TRIM(IFERROR(LEFT(K17,FIND("(",K17)-1),K17))) | AS17: =IF(M17="","",TRIM(IFERROR(LEFT(M17,FIND("(",M17)-1),M17))) | AT17: =IF(O17="","",TRIM(IFERROR(LEFT(O17,FIND("(",O17)-1),O17))) | AU17: =IF(Q17="","",TRIM(IFERROR(LEFT(Q17,FIND("(",Q17)-1),Q17)))
A18: 4 | T18: =IF(B18<>"",TRIM(IFERROR(LEFT(B18,FIND("(",B18)-1),B18)),T17) | U18: =IF(D18<>"",TRIM(IFERROR(LEFT(D18,FIND("(",D18)-1),D18)),U17) | V18: =IF(F18<>"",TRIM(IFERROR(LEFT(F18,FIND("(",F18)-1),F18)),V17) | W18: =IF(H18<>"",TRIM(IFERROR(LEFT(H18,FIND("(",H18)-1),H18)),W17) | X18: =IF(J18<>"",TRIM(IFERROR(LEFT(J18,FIND("(",J18)-1),J18)),X17) | Y18: =IF(L18<>"",TRIM(IFERROR(LEFT(L18,FIND("(",L18)-1),L18)),Y17) | Z18: =IF(N18<>"",TRIM(IFERROR(LEFT(N18,FIND("(",N18)-1),N18)),Z17) | AA18: =IF(P18<>"",TRIM(IFERROR(LEFT(P18,FIND("(",P18)-1),P18)),AA17) | AD18: =IF(C18="","",IF(T18="","(sin responsabilidad)",T18)) | AE18: =IF(E18="","",IF(U18="","(sin responsabilidad)",U18)) | AF18: =IF(G18="","",IF(V18="","(sin responsabilidad)",V18)) | AG18: =IF(I18="","",IF(W18="","(sin responsabilidad)",W18)) | AH18: =IF(K18="","",IF(X18="","(sin responsabilidad)",X18)) | AI18: =IF(M18="","",IF(Y18="","(sin responsabilidad)",Y18)) | AJ18: =IF(O18="","",IF(Z18="","(sin responsabilidad)",Z18)) | AK18: =IF(Q18="","",IF(AA18="","(sin responsabilidad)",AA18)) | AN18: =IF(C18="","",TRIM(IFERROR(LEFT(C18,FIND("(",C18)-1),C18))) | AO18: =IF(E18="","",TRIM(IFERROR(LEFT(E18,FIND("(",E18)-1),E18))) | AP18: =IF(G18="","",TRIM(IFERROR(LEFT(G18,FIND("(",G18)-1),G18))) | AQ18: =IF(I18="","",TRIM(IFERROR(LEFT(I18,FIND("(",I18)-1),I18))) | AR18: =IF(K18="","",TRIM(IFERROR(LEFT(K18,FIND("(",K18)-1),K18))) | AS18: =IF(M18="","",TRIM(IFERROR(LEFT(M18,FIND("(",M18)-1),M18))) | AT18: =IF(O18="","",TRIM(IFERROR(LEFT(O18,FIND("(",O18)-1),O18))) | AU18: =IF(Q18="","",TRIM(IFERROR(LEFT(Q18,FIND("(",Q18)-1),Q18)))
A19: 5 | T19: =IF(B19<>"",TRIM(IFERROR(LEFT(B19,FIND("(",B19)-1),B19)),T18) | U19: =IF(D19<>"",TRIM(IFERROR(LEFT(D19,FIND("(",D19)-1),D19)),U18) | V19: =IF(F19<>"",TRIM(IFERROR(LEFT(F19,FIND("(",F19)-1),F19)),V18) | W19: =IF(H19<>"",TRIM(IFERROR(LEFT(H19,FIND("(",H19)-1),H19)),W18) | X19: =IF(J19<>"",TRIM(IFERROR(LEFT(J19,FIND("(",J19)-1),J19)),X18) | Y19: =IF(L19<>"",TRIM(IFERROR(LEFT(L19,FIND("(",L19)-1),L19)),Y18) | Z19: =IF(N19<>"",TRIM(IFERROR(LEFT(N19,FIND("(",N19)-1),N19)),Z18) | AA19: =IF(P19<>"",TRIM(IFERROR(LEFT(P19,FIND("(",P19)-1),P19)),AA18) | AD19: =IF(C19="","",IF(T19="","(sin responsabilidad)",T19)) | AE19: =IF(E19="","",IF(U19="","(sin responsabilidad)",U19)) | AF19: =IF(G19="","",IF(V19="","(sin responsabilidad)",V19)) | AG19: =IF(I19="","",IF(W19="","(sin responsabilidad)",W19)) | AH19: =IF(K19="","",IF(X19="","(sin responsabilidad)",X19)) | AI19: =IF(M19="","",IF(Y19="","(sin responsabilidad)",Y19)) | AJ19: =IF(O19="","",IF(Z19="","(sin responsabilidad)",Z19)) | AK19: =IF(Q19="","",IF(AA19="","(sin responsabilidad)",AA19)) | AN19: =IF(C19="","",TRIM(IFERROR(LEFT(C19,FIND("(",C19)-1),C19))) | AO19: =IF(E19="","",TRIM(IFERROR(LEFT(E19,FIND("(",E19)-1),E19))) | AP19: =IF(G19="","",TRIM(IFERROR(LEFT(G19,FIND("(",G19)-1),G19))) | AQ19: =IF(I19="","",TRIM(IFERROR(LEFT(I19,FIND("(",I19)-1),I19))) | AR19: =IF(K19="","",TRIM(IFERROR(LEFT(K19,FIND("(",K19)-1),K19))) | AS19: =IF(M19="","",TRIM(IFERROR(LEFT(M19,FIND("(",M19)-1),M19))) | AT19: =IF(O19="","",TRIM(IFERROR(LEFT(O19,FIND("(",O19)-1),O19))) | AU19: =IF(Q19="","",TRIM(IFERROR(LEFT(Q19,FIND("(",Q19)-1),Q19)))
A20: 6 | T20: =IF(B20<>"",TRIM(IFERROR(LEFT(B20,FIND("(",B20)-1),B20)),T19) | U20: =IF(D20<>"",TRIM(IFERROR(LEFT(D20,FIND("(",D20)-1),D20)),U19) | V20: =IF(F20<>"",TRIM(IFERROR(LEFT(F20,FIND("(",F20)-1),F20)),V19) | W20: =IF(H20<>"",TRIM(IFERROR(LEFT(H20,FIND("(",H20)-1),H20)),W19) | X20: =IF(J20<>"",TRIM(IFERROR(LEFT(J20,FIND("(",J20)-1),J20)),X19) | Y20: =IF(L20<>"",TRIM(IFERROR(LEFT(L20,FIND("(",L20)-1),L20)),Y19) | Z20: =IF(N20<>"",TRIM(IFERROR(LEFT(N20,FIND("(",N20)-1),N20)),Z19) | AA20: =IF(P20<>"",TRIM(IFERROR(LEFT(P20,FIND("(",P20)-1),P20)),AA19) | AD20: =IF(C20="","",IF(T20="","(sin responsabilidad)",T20)) | AE20: =IF(E20="","",IF(U20="","(sin responsabilidad)",U20)) | AF20: =IF(G20="","",IF(V20="","(sin responsabilidad)",V20)) | AG20: =IF(I20="","",IF(W20="","(sin responsabilidad)",W20)) | AH20: =IF(K20="","",IF(X20="","(sin responsabilidad)",X20)) | AI20: =IF(M20="","",IF(Y20="","(sin responsabilidad)",Y20)) | AJ20: =IF(O20="","",IF(Z20="","(sin responsabilidad)",Z20)) | AK20: =IF(Q20="","",IF(AA20="","(sin responsabilidad)",AA20)) | AN20: =IF(C20="","",TRIM(IFERROR(LEFT(C20,FIND("(",C20)-1),C20))) | AO20: =IF(E20="","",TRIM(IFERROR(LEFT(E20,FIND("(",E20)-1),E20))) | AP20: =IF(G20="","",TRIM(IFERROR(LEFT(G20,FIND("(",G20)-1),G20))) | AQ20: =IF(I20="","",TRIM(IFERROR(LEFT(I20,FIND("(",I20)-1),I20))) | AR20: =IF(K20="","",TRIM(IFERROR(LEFT(K20,FIND("(",K20)-1),K20))) | AS20: =IF(M20="","",TRIM(IFERROR(LEFT(M20,FIND("(",M20)-1),M20))) | AT20: =IF(O20="","",TRIM(IFERROR(LEFT(O20,FIND("(",O20)-1),O20))) | AU20: =IF(Q20="","",TRIM(IFERROR(LEFT(Q20,FIND("(",Q20)-1),Q20)))
A21: 7 | T21: =IF(B21<>"",TRIM(IFERROR(LEFT(B21,FIND("(",B21)-1),B21)),T20) | U21: =IF(D21<>"",TRIM(IFERROR(LEFT(D21,FIND("(",D21)-1),D21)),U20) | V21: =IF(F21<>"",TRIM(IFERROR(LEFT(F21,FIND("(",F21)-1),F21)),V20) | W21: =IF(H21<>"",TRIM(IFERROR(LEFT(H21,FIND("(",H21)-1),H21)),W20) | X21: =IF(J21<>"",TRIM(IFERROR(LEFT(J21,FIND("(",J21)-1),J21)),X20) | Y21: =IF(L21<>"",TRIM(IFERROR(LEFT(L21,FIND("(",L21)-1),L21)),Y20) | Z21: =IF(N21<>"",TRIM(IFERROR(LEFT(N21,FIND("(",N21)-1),N21)),Z20) | AA21: =IF(P21<>"",TRIM(IFERROR(LEFT(P21,FIND("(",P21)-1),P21)),AA20) | AD21: =IF(C21="","",IF(T21="","(sin responsabilidad)",T21)) | AE21: =IF(E21="","",IF(U21="","(sin responsabilidad)",U21)) | AF21: =IF(G21="","",IF(V21="","(sin responsabilidad)",V21)) | AG21: =IF(I21="","",IF(W21="","(sin responsabilidad)",W21)) | AH21: =IF(K21="","",IF(X21="","(sin responsabilidad)",X21)) | AI21: =IF(M21="","",IF(Y21="","(sin responsabilidad)",Y21)) | AJ21: =IF(O21="","",IF(Z21="","(sin responsabilidad)",Z21)) | AK21: =IF(Q21="","",IF(AA21="","(sin responsabilidad)",AA21)) | AN21: =IF(C21="","",TRIM(IFERROR(LEFT(C21,FIND("(",C21)-1),C21))) | AO21: =IF(E21="","",TRIM(IFERROR(LEFT(E21,FIND("(",E21)-1),E21))) | AP21: =IF(G21="","",TRIM(IFERROR(LEFT(G21,FIND("(",G21)-1),G21))) | AQ21: =IF(I21="","",TRIM(IFERROR(LEFT(I21,FIND("(",I21)-1),I21))) | AR21: =IF(K21="","",TRIM(IFERROR(LEFT(K21,FIND("(",K21)-1),K21))) | AS21: =IF(M21="","",TRIM(IFERROR(LEFT(M21,FIND("(",M21)-1),M21))) | AT21: =IF(O21="","",TRIM(IFERROR(LEFT(O21,FIND("(",O21)-1),O21))) | AU21: =IF(Q21="","",TRIM(IFERROR(LEFT(Q21,FIND("(",Q21)-1),Q21)))
A22: 8 | T22: =IF(B22<>"",TRIM(IFERROR(LEFT(B22,FIND("(",B22)-1),B22)),T21) | U22: =IF(D22<>"",TRIM(IFERROR(LEFT(D22,FIND("(",D22)-1),D22)),U21) | V22: =IF(F22<>"",TRIM(IFERROR(LEFT(F22,FIND("(",F22)-1),F22)),V21) | W22: =IF(H22<>"",TRIM(IFERROR(LEFT(H22,FIND("(",H22)-1),H22)),W21) | X22: =IF(J22<>"",TRIM(IFERROR(LEFT(J22,FIND("(",J22)-1),J22)),X21) | Y22: =IF(L22<>"",TRIM(IFERROR(LEFT(L22,FIND("(",L22)-1),L22)),Y21) | Z22: =IF(N22<>"",TRIM(IFERROR(LEFT(N22,FIND("(",N22)-1),N22)),Z21) | AA22: =IF(P22<>"",TRIM(IFERROR(LEFT(P22,FIND("(",P22)-1),P22)),AA21) | AD22: =IF(C22="","",IF(T22="","(sin responsabilidad)",T22)) | AE22: =IF(E22="","",IF(U22="","(sin responsabilidad)",U22)) | AF22: =IF(G22="","",IF(V22="","(sin responsabilidad)",V22)) | AG22: =IF(I22="","",IF(W22="","(sin responsabilidad)",W22)) | AH22: =IF(K22="","",IF(X22="","(sin responsabilidad)",X22)) | AI22: =IF(M22="","",IF(Y22="","(sin responsabilidad)",Y22)) | AJ22: =IF(O22="","",IF(Z22="","(sin responsabilidad)",Z22)) | AK22: =IF(Q22="","",IF(AA22="","(sin responsabilidad)",AA22)) | AN22: =IF(C22="","",TRIM(IFERROR(LEFT(C22,FIND("(",C22)-1),C22))) | AO22: =IF(E22="","",TRIM(IFERROR(LEFT(E22,FIND("(",E22)-1),E22))) | AP22: =IF(G22="","",TRIM(IFERROR(LEFT(G22,FIND("(",G22)-1),G22))) | AQ22: =IF(I22="","",TRIM(IFERROR(LEFT(I22,FIND("(",I22)-1),I22))) | AR22: =IF(K22="","",TRIM(IFERROR(LEFT(K22,FIND("(",K22)-1),K22))) | AS22: =IF(M22="","",TRIM(IFERROR(LEFT(M22,FIND("(",M22)-1),M22))) | AT22: =IF(O22="","",TRIM(IFERROR(LEFT(O22,FIND("(",O22)-1),O22))) | AU22: =IF(Q22="","",TRIM(IFERROR(LEFT(Q22,FIND("(",Q22)-1),Q22)))
A23: 9 | T23: =IF(B23<>"",TRIM(IFERROR(LEFT(B23,FIND("(",B23)-1),B23)),T22) | U23: =IF(D23<>"",TRIM(IFERROR(LEFT(D23,FIND("(",D23)-1),D23)),U22) | V23: =IF(F23<>"",TRIM(IFERROR(LEFT(F23,FIND("(",F23)-1),F23)),V22) | W23: =IF(H23<>"",TRIM(IFERROR(LEFT(H23,FIND("(",H23)-1),H23)),W22) | X23: =IF(J23<>"",TRIM(IFERROR(LEFT(J23,FIND("(",J23)-1),J23)),X22) | Y23: =IF(L23<>"",TRIM(IFERROR(LEFT(L23,FIND("(",L23)-1),L23)),Y22) | Z23: =IF(N23<>"",TRIM(IFERROR(LEFT(N23,FIND("(",N23)-1),N23)),Z22) | AA23: =IF(P23<>"",TRIM(IFERROR(LEFT(P23,FIND("(",P23)-1),P23)),AA22) | AD23: =IF(C23="","",IF(T23="","(sin responsabilidad)",T23)) | AE23: =IF(E23="","",IF(U23="","(sin responsabilidad)",U23)) | AF23: =IF(G23="","",IF(V23="","(sin responsabilidad)",V23)) | AG23: =IF(I23="","",IF(W23="","(sin responsabilidad)",W23)) | AH23: =IF(K23="","",IF(X23="","(sin responsabilidad)",X23)) | AI23: =IF(M23="","",IF(Y23="","(sin responsabilidad)",Y23)) | AJ23: =IF(O23="","",IF(Z23="","(sin responsabilidad)",Z23)) | AK23: =IF(Q23="","",IF(AA23="","(sin responsabilidad)",AA23)) | AN23: =IF(C23="","",TRIM(IFERROR(LEFT(C23,FIND("(",C23)-1),C23))) | AO23: =IF(E23="","",TRIM(IFERROR(LEFT(E23,FIND("(",E23)-1),E23))) | AP23: =IF(G23="","",TRIM(IFERROR(LEFT(G23,FIND("(",G23)-1),G23))) | AQ23: =IF(I23="","",TRIM(IFERROR(LEFT(I23,FIND("(",I23)-1),I23))) | AR23: =IF(K23="","",TRIM(IFERROR(LEFT(K23,FIND("(",K23)-1),K23))) | AS23: =IF(M23="","",TRIM(IFERROR(LEFT(M23,FIND("(",M23)-1),M23))) | AT23: =IF(O23="","",TRIM(IFERROR(LEFT(O23,FIND("(",O23)-1),O23))) | AU23: =IF(Q23="","",TRIM(IFERROR(LEFT(Q23,FIND("(",Q23)-1),Q23)))
A24: 10 | T24: =IF(B24<>"",TRIM(IFERROR(LEFT(B24,FIND("(",B24)-1),B24)),T23) | U24: =IF(D24<>"",TRIM(IFERROR(LEFT(D24,FIND("(",D24)-1),D24)),U23) | V24: =IF(F24<>"",TRIM(IFERROR(LEFT(F24,FIND("(",F24)-1),F24)),V23) | W24: =IF(H24<>"",TRIM(IFERROR(LEFT(H24,FIND("(",H24)-1),H24)),W23) | X24: =IF(J24<>"",TRIM(IFERROR(LEFT(J24,FIND("(",J24)-1),J24)),X23) | Y24: =IF(L24<>"",TRIM(IFERROR(LEFT(L24,FIND("(",L24)-1),L24)),Y23) | Z24: =IF(N24<>"",TRIM(IFERROR(LEFT(N24,FIND("(",N24)-1),N24)),Z23) | AA24: =IF(P24<>"",TRIM(IFERROR(LEFT(P24,FIND("(",P24)-1),P24)),AA23) | AD24: =IF(C24="","",IF(T24="","(sin responsabilidad)",T24)) | AE24: =IF(E24="","",IF(U24="","(sin responsabilidad)",U24)) | AF24: =IF(G24="","",IF(V24="","(sin responsabilidad)",V24)) | AG24: =IF(I24="","",IF(W24="","(sin responsabilidad)",W24)) | AH24: =IF(K24="","",IF(X24="","(sin responsabilidad)",X24)) | AI24: =IF(M24="","",IF(Y24="","(sin responsabilidad)",Y24)) | AJ24: =IF(O24="","",IF(Z24="","(sin responsabilidad)",Z24)) | AK24: =IF(Q24="","",IF(AA24="","(sin responsabilidad)",AA24)) | AN24: =IF(C24="","",TRIM(IFERROR(LEFT(C24,FIND("(",C24)-1),C24))) | AO24: =IF(E24="","",TRIM(IFERROR(LEFT(E24,FIND("(",E24)-1),E24))) | AP24: =IF(G24="","",TRIM(IFERROR(LEFT(G24,FIND("(",G24)-1),G24))) | AQ24: =IF(I24="","",TRIM(IFERROR(LEFT(I24,FIND("(",I24)-1),I24))) | AR24: =IF(K24="","",TRIM(IFERROR(LEFT(K24,FIND("(",K24)-1),K24))) | AS24: =IF(M24="","",TRIM(IFERROR(LEFT(M24,FIND("(",M24)-1),M24))) | AT24: =IF(O24="","",TRIM(IFERROR(LEFT(O24,FIND("(",O24)-1),O24))) | AU24: =IF(Q24="","",TRIM(IFERROR(LEFT(Q24,FIND("(",Q24)-1),Q24)))
A25: 11 | T25: =IF(B25<>"",TRIM(IFERROR(LEFT(B25,FIND("(",B25)-1),B25)),T24) | U25: =IF(D25<>"",TRIM(IFERROR(LEFT(D25,FIND("(",D25)-1),D25)),U24) | V25: =IF(F25<>"",TRIM(IFERROR(LEFT(F25,FIND("(",F25)-1),F25)),V24) | W25: =IF(H25<>"",TRIM(IFERROR(LEFT(H25,FIND("(",H25)-1),H25)),W24) | X25: =IF(J25<>"",TRIM(IFERROR(LEFT(J25,FIND("(",J25)-1),J25)),X24) | Y25: =IF(L25<>"",TRIM(IFERROR(LEFT(L25,FIND("(",L25)-1),L25)),Y24) | Z25: =IF(N25<>"",TRIM(IFERROR(LEFT(N25,FIND("(",N25)-1),N25)),Z24) | AA25: =IF(P25<>"",TRIM(IFERROR(LEFT(P25,FIND("(",P25)-1),P25)),AA24) | AD25: =IF(C25="","",IF(T25="","(sin responsabilidad)",T25)) | AE25: =IF(E25="","",IF(U25="","(sin responsabilidad)",U25)) | AF25: =IF(G25="","",IF(V25="","(sin responsabilidad)",V25)) | AG25: =IF(I25="","",IF(W25="","(sin responsabilidad)",W25)) | AH25: =IF(K25="","",IF(X25="","(sin responsabilidad)",X25)) | AI25: =IF(M25="","",IF(Y25="","(sin responsabilidad)",Y25)) | AJ25: =IF(O25="","",IF(Z25="","(sin responsabilidad)",Z25)) | AK25: =IF(Q25="","",IF(AA25="","(sin responsabilidad)",AA25)) | AN25: =IF(C25="","",TRIM(IFERROR(LEFT(C25,FIND("(",C25)-1),C25))) | AO25: =IF(E25="","",TRIM(IFERROR(LEFT(E25,FIND("(",E25)-1),E25))) | AP25: =IF(G25="","",TRIM(IFERROR(LEFT(G25,FIND("(",G25)-1),G25))) | AQ25: =IF(I25="","",TRIM(IFERROR(LEFT(I25,FIND("(",I25)-1),I25))) | AR25: =IF(K25="","",TRIM(IFERROR(LEFT(K25,FIND("(",K25)-1),K25))) | AS25: =IF(M25="","",TRIM(IFERROR(LEFT(M25,FIND("(",M25)-1),M25))) | AT25: =IF(O25="","",TRIM(IFERROR(LEFT(O25,FIND("(",O25)-1),O25))) | AU25: =IF(Q25="","",TRIM(IFERROR(LEFT(Q25,FIND("(",Q25)-1),Q25)))
A26: 12 | T26: =IF(B26<>"",TRIM(IFERROR(LEFT(B26,FIND("(",B26)-1),B26)),T25) | U26: =IF(D26<>"",TRIM(IFERROR(LEFT(D26,FIND("(",D26)-1),D26)),U25) | V26: =IF(F26<>"",TRIM(IFERROR(LEFT(F26,FIND("(",F26)-1),F26)),V25) | W26: =IF(H26<>"",TRIM(IFERROR(LEFT(H26,FIND("(",H26)-1),H26)),W25) | X26: =IF(J26<>"",TRIM(IFERROR(LEFT(J26,FIND("(",J26)-1),J26)),X25) | Y26: =IF(L26<>"",TRIM(IFERROR(LEFT(L26,FIND("(",L26)-1),L26)),Y25) | Z26: =IF(N26<>"",TRIM(IFERROR(LEFT(N26,FIND("(",N26)-1),N26)),Z25) | AA26: =IF(P26<>"",TRIM(IFERROR(LEFT(P26,FIND("(",P26)-1),P26)),AA25) | AD26: =IF(C26="","",IF(T26="","(sin responsabilidad)",T26)) | AE26: =IF(E26="","",IF(U26="","(sin responsabilidad)",U26)) | AF26: =IF(G26="","",IF(V26="","(sin responsabilidad)",V26)) | AG26: =IF(I26="","",IF(W26="","(sin responsabilidad)",W26)) | AH26: =IF(K26="","",IF(X26="","(sin responsabilidad)",X26)) | AI26: =IF(M26="","",IF(Y26="","(sin responsabilidad)",Y26)) | AJ26: =IF(O26="","",IF(Z26="","(sin responsabilidad)",Z26)) | AK26: =IF(Q26="","",IF(AA26="","(sin responsabilidad)",AA26)) | AN26: =IF(C26="","",TRIM(IFERROR(LEFT(C26,FIND("(",C26)-1),C26))) | AO26: =IF(E26="","",TRIM(IFERROR(LEFT(E26,FIND("(",E26)-1),E26))) | AP26: =IF(G26="","",TRIM(IFERROR(LEFT(G26,FIND("(",G26)-1),G26))) | AQ26: =IF(I26="","",TRIM(IFERROR(LEFT(I26,FIND("(",I26)-1),I26))) | AR26: =IF(K26="","",TRIM(IFERROR(LEFT(K26,FIND("(",K26)-1),K26))) | AS26: =IF(M26="","",TRIM(IFERROR(LEFT(M26,FIND("(",M26)-1),M26))) | AT26: =IF(O26="","",TRIM(IFERROR(LEFT(O26,FIND("(",O26)-1),O26))) | AU26: =IF(Q26="","",TRIM(IFERROR(LEFT(Q26,FIND("(",Q26)-1),Q26)))
A27: 13 | T27: =IF(B27<>"",TRIM(IFERROR(LEFT(B27,FIND("(",B27)-1),B27)),T26) | U27: =IF(D27<>"",TRIM(IFERROR(LEFT(D27,FIND("(",D27)-1),D27)),U26) | V27: =IF(F27<>"",TRIM(IFERROR(LEFT(F27,FIND("(",F27)-1),F27)),V26) | W27: =IF(H27<>"",TRIM(IFERROR(LEFT(H27,FIND("(",H27)-1),H27)),W26) | X27: =IF(J27<>"",TRIM(IFERROR(LEFT(J27,FIND("(",J27)-1),J27)),X26) | Y27: =IF(L27<>"",TRIM(IFERROR(LEFT(L27,FIND("(",L27)-1),L27)),Y26) | Z27: =IF(N27<>"",TRIM(IFERROR(LEFT(N27,FIND("(",N27)-1),N27)),Z26) | AA27: =IF(P27<>"",TRIM(IFERROR(LEFT(P27,FIND("(",P27)-1),P27)),AA26) | AD27: =IF(C27="","",IF(T27="","(sin responsabilidad)",T27)) | AE27: =IF(E27="","",IF(U27="","(sin responsabilidad)",U27)) | AF27: =IF(G27="","",IF(V27="","(sin responsabilidad)",V27)) | AG27: =IF(I27="","",IF(W27="","(sin responsabilidad)",W27)) | AH27: =IF(K27="","",IF(X27="","(sin responsabilidad)",X27)) | AI27: =IF(M27="","",IF(Y27="","(sin responsabilidad)",Y27)) | AJ27: =IF(O27="","",IF(Z27="","(sin responsabilidad)",Z27)) | AK27: =IF(Q27="","",IF(AA27="","(sin responsabilidad)",AA27)) | AN27: =IF(C27="","",TRIM(IFERROR(LEFT(C27,FIND("(",C27)-1),C27))) | AO27: =IF(E27="","",TRIM(IFERROR(LEFT(E27,FIND("(",E27)-1),E27))) | AP27: =IF(G27="","",TRIM(IFERROR(LEFT(G27,FIND("(",G27)-1),G27))) | AQ27: =IF(I27="","",TRIM(IFERROR(LEFT(I27,FIND("(",I27)-1),I27))) | AR27: =IF(K27="","",TRIM(IFERROR(LEFT(K27,FIND("(",K27)-1),K27))) | AS27: =IF(M27="","",TRIM(IFERROR(LEFT(M27,FIND("(",M27)-1),M27))) | AT27: =IF(O27="","",TRIM(IFERROR(LEFT(O27,FIND("(",O27)-1),O27))) | AU27: =IF(Q27="","",TRIM(IFERROR(LEFT(Q27,FIND("(",Q27)-1),Q27)))
... A64: 50 | T64: =IF(B64<>"",TRIM(IFERROR(LEFT(B64,FIND("(",B64)-1),B64)),T63) | U64: =IF(D64<>"",TRIM(IFERROR(LEFT(D64,FIND("(",D64)-1),D64)),U63) | V64: =IF(F64<>"",TRIM(IFERROR(LEFT(F64,FIND("(",F64)-1),F64)),V63) | W64: =IF(H64<>"",TRIM(IFERROR(LEFT(H64,FIND("(",H64)-1),H64)),W63) | X64: =IF(J64<>"",TRIM(IFERROR(LEFT(J64,FIND("(",J64)-1),J64)),X63) | Y64: =IF(L64<>"",TRIM(IFERROR(LEFT(L64,FIND("(",L64)-1),L64)),Y63) | Z64: =IF(N64<>"",TRIM(IFERROR(LEFT(N64,FIND("(",N64)-1),N64)),Z63) | AA64: =IF(P64<>"",TRIM(IFERROR(LEFT(P64,FIND("(",P64)-1),P64)),AA63) | AD64: =IF(C64="","",IF(T64="","(sin responsabilidad)",T64)) | AE64: =IF(E64="","",IF(U64="","(sin responsabilidad)",U64)) | AF64: =IF(G64="","",IF(V64="","(sin responsabilidad)",V64)) | AG64: =IF(I64="","",IF(W64="","(sin responsabilidad)",W64)) | AH64: =IF(K64="","",IF(X64="","(sin responsabilidad)",X64)) | AI64: =IF(M64="","",IF(Y64="","(sin responsabilidad)",Y64)) | AJ64: =IF(O64="","",IF(Z64="","(sin responsabilidad)",Z64)) | AK64: =IF(Q64="","",IF(AA64="","(sin responsabilidad)",AA64)) | AN64: =IF(C64="","",TRIM(IFERROR(LEFT(C64,FIND("(",C64)-1),C64))) | AO64: =IF(E64="","",TRIM(IFERROR(LEFT(E64,FIND("(",E64)-1),E64))) | AP64: =IF(G64="","",TRIM(IFERROR(LEFT(G64,FIND("(",G64)-1),G64))) | AQ64: =IF(I64="","",TRIM(IFERROR(LEFT(I64,FIND("(",I64)-1),I64))) | AR64: =IF(K64="","",TRIM(IFERROR(LEFT(K64,FIND("(",K64)-1),K64))) | AS64: =IF(M64="","",TRIM(IFERROR(LEFT(M64,FIND("(",M64)-1),M64))) | AT64: =IF(O64="","",TRIM(IFERROR(LEFT(O64,FIND("(",O64)-1),O64))) | AU64: =IF(Q64="","",TRIM(IFERROR(LEFT(Q64,FIND("(",Q64)-1),Q64)))

Sheet Ejemplo
A1: PLAN DEL DÍA | B1: Fecha / Date: | C1: 46314 | F1: Total personas / people: | G1: =B13+D13+F13+H13+J13+L13+N13+P13 -> 124 | I1: Nombres repetidos / Repeated: | J1: =SUMPRODUCT(($AN$6:$AU$64<>"")*(COUNTIF($AN$6:$AU$64,$AN$6:$AU$64)>1)) -> 0
A2: EJEMPLO (de la foto del 19/10, con nombres como están en Connecteam). No se conecta con Resumen. / Sample only.
A3: Proyecto / Project | B3: Bucking | D3: Prerolls | F3: Trimming | H3: Harvest Intake | J3: Harvest | L3: Watering | N3: Fresh Frozen
A4: Sitio / Site | B4: Adobe | D4: Adobe | F4: Adobe | H4: Adobe | J4: Comstock | L4: Wildcat | N4: Sulphur Bank
A5: Horario: inicio | fin | B5: 7am | C5: 3:30pm | D5: 7am | E5: 3:30pm | F5: 7am | G5: 3:30pm | H5: 5am | I5: 2pm | J5: 4am | K5: 12:30pm | L5: 7am | M5: 3:30pm | N5: 7am | O5: 3:30pm
A6: Líder / Lead | D6: Jesus Ayerin Sicairos | J6: Yobani Vega | N6: Juan J. Parra | AN6: =IF(B6="","",TRIM(IFERROR(LEFT(B6,FIND("(",B6)-1),B6))) | AO6: =IF(D6="","",TRIM(IFERROR(LEFT(D6,FIND("(",D6)-1),D6))) -> Jesus Ayerin Sicairos | AP6: =IF(F6="","",TRIM(IFERROR(LEFT(F6,FIND("(",F6)-1),F6))) | AQ6: =IF(H6="","",TRIM(IFERROR(LEFT(H6,FIND("(",H6)-1),H6))) | AR6: =IF(J6="","",TRIM(IFERROR(LEFT(J6,FIND("(",J6)-1),J6))) -> Yobani Vega | AS6: =IF(L6="","",TRIM(IFERROR(LEFT(L6,FIND("(",L6)-1),L6))) | AT6: =IF(N6="","",TRIM(IFERROR(LEFT(N6,FIND("(",N6)-1),N6))) -> Juan J. Parra | AU6: =IF(P6="","",TRIM(IFERROR(LEFT(P6,FIND("(",P6)-1),P6)))
A7: Contratista 1: nombre | cuántos | F7: Juan | G7: 15 | H7: Juan | I7: 8 | J7: Juan | K7: 10 | N7: Juan | O7: 20
A8: Contratista 1: inicio | fin
A9: Contratista 2: nombre | cuántos | H9: Juan | I9: 15
A10: Contratista 2: inicio | fin | H10: 5:30pm | I10: 2am
A11: Notas / Notes | H11: Colgar a las 5:30pm: contratista 2
A12: Nombrados (incl. líder) | B12: =(B6<>"")+COUNTA(C15:C64) -> 21 | D12: =(D6<>"")+COUNTA(E15:E64) -> 6 | F12: =(F6<>"")+COUNTA(G15:G64) -> 0 | H12: =(H6<>"")+COUNTA(I15:I64) -> 10 | J12: =(J6<>"")+COUNTA(K15:K64) -> 14 | L12: =(L6<>"")+COUNTA(M15:M64) -> 1 | N12: =(N6<>"")+COUNTA(O15:O64) -> 4 | P12: =(P6<>"")+COUNTA(Q15:Q64) -> 0
A13: TOTAL (con contratistas) | B13: =B12+N(C7)+N(C9) -> 21 | D13: =D12+N(E7)+N(E9) -> 6 | F13: =F12+N(G7)+N(G9) -> 15 | H13: =H12+N(I7)+N(I9) -> 33 | J13: =J12+N(K7)+N(K9) -> 24 | L13: =L12+N(M7)+N(M9) -> 1 | N13: =N12+N(O7)+N(O9) -> 24 | P13: =P12+N(Q7)+N(Q9) -> 0
A14: Responsabilidad | Nombre ↓ | B14: Responsabilidad | C14: Nombre | D14: Responsabilidad | E14: Nombre | F14: Responsabilidad | G14: Nombre | H14: Responsabilidad | I14: Nombre | J14: Responsabilidad | K14: Nombre | L14: Responsabilidad | M14: Nombre | N14: Responsabilidad | O14: Nombre | P14: Responsabilidad | Q14: Nombre
A15: 1 | B15: Destronche | C15: Isabel Hernandez | D15: Prerolls | E15: Vianey Zazueta | H15: Colgar | I15: Jorge Santiago Calvo | J15: Cortar | K15: Jose Guadalupe Lopez | L15: Regar | M15: Isai Cruz Lopez | N15: Fresh frozen | O15: Anastasia Santiago | T15: =IF(B15<>"",TRIM(IFERROR(LEFT(B15,FIND("(",B15)-1),B15)),"") -> Destronche | U15: =IF(D15<>"",TRIM(IFERROR(LEFT(D15,FIND("(",D15)-1),D15)),"") -> Prerolls | V15: =IF(F15<>"",TRIM(IFERROR(LEFT(F15,FIND("(",F15)-1),F15)),"") | W15: =IF(H15<>"",TRIM(IFERROR(LEFT(H15,FIND("(",H15)-1),H15)),"") -> Colgar | X15: =IF(J15<>"",TRIM(IFERROR(LEFT(J15,FIND("(",J15)-1),J15)),"") -> Cortar | Y15: =IF(L15<>"",TRIM(IFERROR(LEFT(L15,FIND("(",L15)-1),L15)),"") -> Regar | Z15: =IF(N15<>"",TRIM(IFERROR(LEFT(N15,FIND("(",N15)-1),N15)),"") -> Fresh frozen | AA15: =IF(P15<>"",TRIM(IFERROR(LEFT(P15,FIND("(",P15)-1),P15)),"") | AD15: =IF(C15="","",IF(T15="","(sin responsabilidad)",T15)) -> Destronche | AE15: =IF(E15="","",IF(U15="","(sin responsabilidad)",U15)) -> Prerolls | AF15: =IF(G15="","",IF(V15="","(sin responsabilidad)",V15)) | AG15: =IF(I15="","",IF(W15="","(sin responsabilidad)",W15)) -> Colgar | AH15: =IF(K15="","",IF(X15="","(sin responsabilidad)",X15)) -> Cortar | AI15: =IF(M15="","",IF(Y15="","(sin responsabilidad)",Y15)) -> Regar | AJ15: =IF(O15="","",IF(Z15="","(sin responsabilidad)",Z15)) -> Fresh frozen | AK15: =IF(Q15="","",IF(AA15="","(sin responsabilidad)",AA15)) | AN15: =IF(C15="","",TRIM(IFERROR(LEFT(C15,FIND("(",C15)-1),C15))) -> Isabel Hernandez | AO15: =IF(E15="","",TRIM(IFERROR(LEFT(E15,FIND("(",E15)-1),E15))) -> Vianey Zazueta | AP15: =IF(G15="","",TRIM(IFERROR(LEFT(G15,FIND("(",G15)-1),G15))) | AQ15: =IF(I15="","",TRIM(IFERROR(LEFT(I15,FIND("(",I15)-1),I15))) -> Jorge Santiago Calvo | AR15: =IF(K15="","",TRIM(IFERROR(LEFT(K15,FIND("(",K15)-1),K15))) -> Jose Guadalupe Lopez | AS15: =IF(M15="","",TRIM(IFERROR(LEFT(M15,FIND("(",M15)-1),M15))) -> Isai Cruz Lopez | AT15: =IF(O15="","",TRIM(IFERROR(LEFT(O15,FIND("(",O15)-1),O15))) -> Anastasia Santiago | AU15: =IF(Q15="","",TRIM(IFERROR(LEFT(Q15,FIND("(",Q15)-1),Q15)))
A16: 2 | C16: Araceli Martinez | E16: Araceli Muniz | I16: Jesus Medina | K16: Diego Lopez | O16: Carla Gomez Perez | T16: =IF(B16<>"",TRIM(IFERROR(LEFT(B16,FIND("(",B16)-1),B16)),T15) -> Destronche | U16: =IF(D16<>"",TRIM(IFERROR(LEFT(D16,FIND("(",D16)-1),D16)),U15) -> Prerolls | V16: =IF(F16<>"",TRIM(IFERROR(LEFT(F16,FIND("(",F16)-1),F16)),V15) | W16: =IF(H16<>"",TRIM(IFERROR(LEFT(H16,FIND("(",H16)-1),H16)),W15) -> Colgar | X16: =IF(J16<>"",TRIM(IFERROR(LEFT(J16,FIND("(",J16)-1),J16)),X15) -> Cortar | Y16: =IF(L16<>"",TRIM(IFERROR(LEFT(L16,FIND("(",L16)-1),L16)),Y15) -> Regar | Z16: =IF(N16<>"",TRIM(IFERROR(LEFT(N16,FIND("(",N16)-1),N16)),Z15) -> Fresh frozen | AA16: =IF(P16<>"",TRIM(IFERROR(LEFT(P16,FIND("(",P16)-1),P16)),AA15) | AD16: =IF(C16="","",IF(T16="","(sin responsabilidad)",T16)) -> Destronche | AE16: =IF(E16="","",IF(U16="","(sin responsabilidad)",U16)) -> Prerolls | AF16: =IF(G16="","",IF(V16="","(sin responsabilidad)",V16)) | AG16: =IF(I16="","",IF(W16="","(sin responsabilidad)",W16)) -> Colgar | AH16: =IF(K16="","",IF(X16="","(sin responsabilidad)",X16)) -> Cortar | AI16: =IF(M16="","",IF(Y16="","(sin responsabilidad)",Y16)) | AJ16: =IF(O16="","",IF(Z16="","(sin responsabilidad)",Z16)) -> Fresh frozen | AK16: =IF(Q16="","",IF(AA16="","(sin responsabilidad)",AA16)) | AN16: =IF(C16="","",TRIM(IFERROR(LEFT(C16,FIND("(",C16)-1),C16))) -> Araceli Martinez | AO16: =IF(E16="","",TRIM(IFERROR(LEFT(E16,FIND("(",E16)-1),E16))) -> Araceli Muniz | AP16: =IF(G16="","",TRIM(IFERROR(LEFT(G16,FIND("(",G16)-1),G16))) | AQ16: =IF(I16="","",TRIM(IFERROR(LEFT(I16,FIND("(",I16)-1),I16))) -> Jesus Medina | AR16: =IF(K16="","",TRIM(IFERROR(LEFT(K16,FIND("(",K16)-1),K16))) -> Diego Lopez | AS16: =IF(M16="","",TRIM(IFERROR(LEFT(M16,FIND("(",M16)-1),M16))) | AT16: =IF(O16="","",TRIM(IFERROR(LEFT(O16,FIND("(",O16)-1),O16))) -> Carla Gomez Perez | AU16: =IF(Q16="","",TRIM(IFERROR(LEFT(Q16,FIND("(",Q16)-1),Q16)))
A17: 3 | C17: Gandy Cardenas | E17: Sirenia Zurita | I17: Jenri Yobani Lopez Lopez | K17: Jose Fredi Aguilar L. | O17: Aurelia Rosales | T17: =IF(B17<>"",TRIM(IFERROR(LEFT(B17,FIND("(",B17)-1),B17)),T16) -> Destronche | U17: =IF(D17<>"",TRIM(IFERROR(LEFT(D17,FIND("(",D17)-1),D17)),U16) -> Prerolls | V17: =IF(F17<>"",TRIM(IFERROR(LEFT(F17,FIND("(",F17)-1),F17)),V16) | W17: =IF(H17<>"",TRIM(IFERROR(LEFT(H17,FIND("(",H17)-1),H17)),W16) -> Colgar | X17: =IF(J17<>"",TRIM(IFERROR(LEFT(J17,FIND("(",J17)-1),J17)),X16) -> Cortar | Y17: =IF(L17<>"",TRIM(IFERROR(LEFT(L17,FIND("(",L17)-1),L17)),Y16) -> Regar | Z17: =IF(N17<>"",TRIM(IFERROR(LEFT(N17,FIND("(",N17)-1),N17)),Z16) -> Fresh frozen | AA17: =IF(P17<>"",TRIM(IFERROR(LEFT(P17,FIND("(",P17)-1),P17)),AA16) | AD17: =IF(C17="","",IF(T17="","(sin responsabilidad)",T17)) -> Destronche | AE17: =IF(E17="","",IF(U17="","(sin responsabilidad)",U17)) -> Prerolls | AF17: =IF(G17="","",IF(V17="","(sin responsabilidad)",V17)) | AG17: =IF(I17="","",IF(W17="","(sin responsabilidad)",W17)) -> Colgar | AH17: =IF(K17="","",IF(X17="","(sin responsabilidad)",X17)) -> Cortar | AI17: =IF(M17="","",IF(Y17="","(sin responsabilidad)",Y17)) | AJ17: =IF(O17="","",IF(Z17="","(sin responsabilidad)",Z17)) -> Fresh frozen | AK17: =IF(Q17="","",IF(AA17="","(sin responsabilidad)",AA17)) | AN17: =IF(C17="","",TRIM(IFERROR(LEFT(C17,FIND("(",C17)-1),C17))) -> Gandy Cardenas | AO17: =IF(E17="","",TRIM(IFERROR(LEFT(E17,FIND("(",E17)-1),E17))) -> Sirenia Zurita | AP17: =IF(G17="","",TRIM(IFERROR(LEFT(G17,FIND("(",G17)-1),G17))) | AQ17: =IF(I17="","",TRIM(IFERROR(LEFT(I17,FIND("(",I17)-1),I17))) -> Jenri Yobani Lopez Lopez | AR17: =IF(K17="","",TRIM(IFERROR(LEFT(K17,FIND("(",K17)-1),K17))) -> Jose Fredi Aguilar L. | AS17: =IF(M17="","",TRIM(IFERROR(LEFT(M17,FIND("(",M17)-1),M17))) | AT17: =IF(O17="","",TRIM(IFERROR(LEFT(O17,FIND("(",O17)-1),O17))) -> Aurelia Rosales | AU17: =IF(Q17="","",TRIM(IFERROR(LEFT(Q17,FIND("(",Q17)-1),Q17)))
A18: 4 | C18: Ramona Ortiz | E18: Ana Reyes | I18: Carlos Tentle | K18: Ismael Cruz | T18: =IF(B18<>"",TRIM(IFERROR(LEFT(B18,FIND("(",B18)-1),B18)),T17) -> Destronche | U18: =IF(D18<>"",TRIM(IFERROR(LEFT(D18,FIND("(",D18)-1),D18)),U17) -> Prerolls | V18: =IF(F18<>"",TRIM(IFERROR(LEFT(F18,FIND("(",F18)-1),F18)),V17) | W18: =IF(H18<>"",TRIM(IFERROR(LEFT(H18,FIND("(",H18)-1),H18)),W17) -> Colgar | X18: =IF(J18<>"",TRIM(IFERROR(LEFT(J18,FIND("(",J18)-1),J18)),X17) -> Cortar | Y18: =IF(L18<>"",TRIM(IFERROR(LEFT(L18,FIND("(",L18)-1),L18)),Y17) -> Regar | Z18: =IF(N18<>"",TRIM(IFERROR(LEFT(N18,FIND("(",N18)-1),N18)),Z17) -> Fresh frozen | AA18: =IF(P18<>"",TRIM(IFERROR(LEFT(P18,FIND("(",P18)-1),P18)),AA17) | AD18: =IF(C18="","",IF(T18="","(sin responsabilidad)",T18)) -> Destronche | AE18: =IF(E18="","",IF(U18="","(sin responsabilidad)",U18)) -> Prerolls | AF18: =IF(G18="","",IF(V18="","(sin responsabilidad)",V18)) | AG18: =IF(I18="","",IF(W18="","(sin responsabilidad)",W18)) -> Colgar | AH18: =IF(K18="","",IF(X18="","(sin responsabilidad)",X18)) -> Cortar | AI18: =IF(M18="","",IF(Y18="","(sin responsabilidad)",Y18)) | AJ18: =IF(O18="","",IF(Z18="","(sin responsabilidad)",Z18)) | AK18: =IF(Q18="","",IF(AA18="","(sin responsabilidad)",AA18)) | AN18: =IF(C18="","",TRIM(IFERROR(LEFT(C18,FIND("(",C18)-1),C18))) -> Ramona Ortiz | AO18: =IF(E18="","",TRIM(IFERROR(LEFT(E18,FIND("(",E18)-1),E18))) -> Ana Reyes | AP18: =IF(G18="","",TRIM(IFERROR(LEFT(G18,FIND("(",G18)-1),G18))) | AQ18: =IF(I18="","",TRIM(IFERROR(LEFT(I18,FIND("(",I18)-1),I18))) -> Carlos Tentle | AR18: =IF(K18="","",TRIM(IFERROR(LEFT(K18,FIND("(",K18)-1),K18))) -> Ismael Cruz | AS18: =IF(M18="","",TRIM(IFERROR(LEFT(M18,FIND("(",M18)-1),M18))) | AT18: =IF(O18="","",TRIM(IFERROR(LEFT(O18,FIND("(",O18)-1),O18))) | AU18: =IF(Q18="","",TRIM(IFERROR(LEFT(Q18,FIND("(",Q18)-1),Q18)))
A19: 5 | C19: Dalett Castro | D19: Packing | E19: Maria Toledo | I19: Roberto Castro | K19: Lisandro Molina | T19: =IF(B19<>"",TRIM(IFERROR(LEFT(B19,FIND("(",B19)-1),B19)),T18) -> Destronche | U19: =IF(D19<>"",TRIM(IFERROR(LEFT(D19,FIND("(",D19)-1),D19)),U18) -> Packing | V19: =IF(F19<>"",TRIM(IFERROR(LEFT(F19,FIND("(",F19)-1),F19)),V18) | W19: =IF(H19<>"",TRIM(IFERROR(LEFT(H19,FIND("(",H19)-1),H19)),W18) -> Colgar | X19: =IF(J19<>"",TRIM(IFERROR(LEFT(J19,FIND("(",J19)-1),J19)),X18) -> Cortar | Y19: =IF(L19<>"",TRIM(IFERROR(LEFT(L19,FIND("(",L19)-1),L19)),Y18) -> Regar | Z19: =IF(N19<>"",TRIM(IFERROR(LEFT(N19,FIND("(",N19)-1),N19)),Z18) -> Fresh frozen | AA19: =IF(P19<>"",TRIM(IFERROR(LEFT(P19,FIND("(",P19)-1),P19)),AA18) | AD19: =IF(C19="","",IF(T19="","(sin responsabilidad)",T19)) -> Destronche | AE19: =IF(E19="","",IF(U19="","(sin responsabilidad)",U19)) -> Packing | AF19: =IF(G19="","",IF(V19="","(sin responsabilidad)",V19)) | AG19: =IF(I19="","",IF(W19="","(sin responsabilidad)",W19)) -> Colgar | AH19: =IF(K19="","",IF(X19="","(sin responsabilidad)",X19)) -> Cortar | AI19: =IF(M19="","",IF(Y19="","(sin responsabilidad)",Y19)) | AJ19: =IF(O19="","",IF(Z19="","(sin responsabilidad)",Z19)) | AK19: =IF(Q19="","",IF(AA19="","(sin responsabilidad)",AA19)) | AN19: =IF(C19="","",TRIM(IFERROR(LEFT(C19,FIND("(",C19)-1),C19))) -> Dalett Castro | AO19: =IF(E19="","",TRIM(IFERROR(LEFT(E19,FIND("(",E19)-1),E19))) -> Maria Toledo | AP19: =IF(G19="","",TRIM(IFERROR(LEFT(G19,FIND("(",G19)-1),G19))) | AQ19: =IF(I19="","",TRIM(IFERROR(LEFT(I19,FIND("(",I19)-1),I19))) -> Roberto Castro | AR19: =IF(K19="","",TRIM(IFERROR(LEFT(K19,FIND("(",K19)-1),K19))) -> Lisandro Molina | AS19: =IF(M19="","",TRIM(IFERROR(LEFT(M19,FIND("(",M19)-1),M19))) | AT19: =IF(O19="","",TRIM(IFERROR(LEFT(O19,FIND("(",O19)-1),O19))) | AU19: =IF(Q19="","",TRIM(IFERROR(LEFT(Q19,FIND("(",Q19)-1),Q19)))
A20: 6 | C20: Maria C Pille | I20: Juan Carlos Lopez | K20: Jonathan Garcia Perez | T20: =IF(B20<>"",TRIM(IFERROR(LEFT(B20,FIND("(",B20)-1),B20)),T19) -> Destronche | U20: =IF(D20<>"",TRIM(IFERROR(LEFT(D20,FIND("(",D20)-1),D20)),U19) -> Packing | V20: =IF(F20<>"",TRIM(IFERROR(LEFT(F20,FIND("(",F20)-1),F20)),V19) | W20: =IF(H20<>"",TRIM(IFERROR(LEFT(H20,FIND("(",H20)-1),H20)),W19) -> Colgar | X20: =IF(J20<>"",TRIM(IFERROR(LEFT(J20,FIND("(",J20)-1),J20)),X19) -> Cortar | Y20: =IF(L20<>"",TRIM(IFERROR(LEFT(L20,FIND("(",L20)-1),L20)),Y19) -> Regar | Z20: =IF(N20<>"",TRIM(IFERROR(LEFT(N20,FIND("(",N20)-1),N20)),Z19) -> Fresh frozen | AA20: =IF(P20<>"",TRIM(IFERROR(LEFT(P20,FIND("(",P20)-1),P20)),AA19) | AD20: =IF(C20="","",IF(T20="","(sin responsabilidad)",T20)) -> Destronche | AE20: =IF(E20="","",IF(U20="","(sin responsabilidad)",U20)) | AF20: =IF(G20="","",IF(V20="","(sin responsabilidad)",V20)) | AG20: =IF(I20="","",IF(W20="","(sin responsabilidad)",W20)) -> Colgar | AH20: =IF(K20="","",IF(X20="","(sin responsabilidad)",X20)) -> Cortar | AI20: =IF(M20="","",IF(Y20="","(sin responsabilidad)",Y20)) | AJ20: =IF(O20="","",IF(Z20="","(sin responsabilidad)",Z20)) | AK20: =IF(Q20="","",IF(AA20="","(sin responsabilidad)",AA20)) | AN20: =IF(C20="","",TRIM(IFERROR(LEFT(C20,FIND("(",C20)-1),C20))) -> Maria C Pille | AO20: =IF(E20="","",TRIM(IFERROR(LEFT(E20,FIND("(",E20)-1),E20))) | AP20: =IF(G20="","",TRIM(IFERROR(LEFT(G20,FIND("(",G20)-1),G20))) | AQ20: =IF(I20="","",TRIM(IFERROR(LEFT(I20,FIND("(",I20)-1),I20))) -> Juan Carlos Lopez | AR20: =IF(K20="","",TRIM(IFERROR(LEFT(K20,FIND("(",K20)-1),K20))) -> Jonathan Garcia Perez | AS20: =IF(M20="","",TRIM(IFERROR(LEFT(M20,FIND("(",M20)-1),M20))) | AT20: =IF(O20="","",TRIM(IFERROR(LEFT(O20,FIND("(",O20)-1),O20))) | AU20: =IF(Q20="","",TRIM(IFERROR(LEFT(Q20,FIND("(",Q20)-1),Q20)))
A21: 7 | C21: Elena Garnica | I21: David Martinez Juarez | K21: Alvaro Cruz Lopez | T21: =IF(B21<>"",TRIM(IFERROR(LEFT(B21,FIND("(",B21)-1),B21)),T20) -> Destronche | U21: =IF(D21<>"",TRIM(IFERROR(LEFT(D21,FIND("(",D21)-1),D21)),U20) -> Packing | V21: =IF(F21<>"",TRIM(IFERROR(LEFT(F21,FIND("(",F21)-1),F21)),V20) | W21: =IF(H21<>"",TRIM(IFERROR(LEFT(H21,FIND("(",H21)-1),H21)),W20) -> Colgar | X21: =IF(J21<>"",TRIM(IFERROR(LEFT(J21,FIND("(",J21)-1),J21)),X20) -> Cortar | Y21: =IF(L21<>"",TRIM(IFERROR(LEFT(L21,FIND("(",L21)-1),L21)),Y20) -> Regar | Z21: =IF(N21<>"",TRIM(IFERROR(LEFT(N21,FIND("(",N21)-1),N21)),Z20) -> Fresh frozen | AA21: =IF(P21<>"",TRIM(IFERROR(LEFT(P21,FIND("(",P21)-1),P21)),AA20) | AD21: =IF(C21="","",IF(T21="","(sin responsabilidad)",T21)) -> Destronche | AE21: =IF(E21="","",IF(U21="","(sin responsabilidad)",U21)) | AF21: =IF(G21="","",IF(V21="","(sin responsabilidad)",V21)) | AG21: =IF(I21="","",IF(W21="","(sin responsabilidad)",W21)) -> Colgar | AH21: =IF(K21="","",IF(X21="","(sin responsabilidad)",X21)) -> Cortar | AI21: =IF(M21="","",IF(Y21="","(sin responsabilidad)",Y21)) | AJ21: =IF(O21="","",IF(Z21="","(sin responsabilidad)",Z21)) | AK21: =IF(Q21="","",IF(AA21="","(sin responsabilidad)",AA21)) | AN21: =IF(C21="","",TRIM(IFERROR(LEFT(C21,FIND("(",C21)-1),C21))) -> Elena Garnica | AO21: =IF(E21="","",TRIM(IFERROR(LEFT(E21,FIND("(",E21)-1),E21))) | AP21: =IF(G21="","",TRIM(IFERROR(LEFT(G21,FIND("(",G21)-1),G21))) | AQ21: =IF(I21="","",TRIM(IFERROR(LEFT(I21,FIND("(",I21)-1),I21))) -> David Martinez Juarez | AR21: =IF(K21="","",TRIM(IFERROR(LEFT(K21,FIND("(",K21)-1),K21))) -> Alvaro Cruz Lopez | AS21: =IF(M21="","",TRIM(IFERROR(LEFT(M21,FIND("(",M21)-1),M21))) | AT21: =IF(O21="","",TRIM(IFERROR(LEFT(O21,FIND("(",O21)-1),O21))) | AU21: =IF(Q21="","",TRIM(IFERROR(LEFT(Q21,FIND("(",Q21)-1),Q21)))
A22: 8 | B22: Desoje | C22: Rosa Baeza | I22: Alex Palacios | K22: Edi Yunue Vega Bustamante | T22: =IF(B22<>"",TRIM(IFERROR(LEFT(B22,FIND("(",B22)-1),B22)),T21) -> Desoje | U22: =IF(D22<>"",TRIM(IFERROR(LEFT(D22,FIND("(",D22)-1),D22)),U21) -> Packing | V22: =IF(F22<>"",TRIM(IFERROR(LEFT(F22,FIND("(",F22)-1),F22)),V21) | W22: =IF(H22<>"",TRIM(IFERROR(LEFT(H22,FIND("(",H22)-1),H22)),W21) -> Colgar | X22: =IF(J22<>"",TRIM(IFERROR(LEFT(J22,FIND("(",J22)-1),J22)),X21) -> Cortar | Y22: =IF(L22<>"",TRIM(IFERROR(LEFT(L22,FIND("(",L22)-1),L22)),Y21) -> Regar | Z22: =IF(N22<>"",TRIM(IFERROR(LEFT(N22,FIND("(",N22)-1),N22)),Z21) -> Fresh frozen | AA22: =IF(P22<>"",TRIM(IFERROR(LEFT(P22,FIND("(",P22)-1),P22)),AA21) | AD22: =IF(C22="","",IF(T22="","(sin responsabilidad)",T22)) -> Desoje | AE22: =IF(E22="","",IF(U22="","(sin responsabilidad)",U22)) | AF22: =IF(G22="","",IF(V22="","(sin responsabilidad)",V22)) | AG22: =IF(I22="","",IF(W22="","(sin responsabilidad)",W22)) -> Colgar | AH22: =IF(K22="","",IF(X22="","(sin responsabilidad)",X22)) -> Cortar | AI22: =IF(M22="","",IF(Y22="","(sin responsabilidad)",Y22)) | AJ22: =IF(O22="","",IF(Z22="","(sin responsabilidad)",Z22)) | AK22: =IF(Q22="","",IF(AA22="","(sin responsabilidad)",AA22)) | AN22: =IF(C22="","",TRIM(IFERROR(LEFT(C22,FIND("(",C22)-1),C22))) -> Rosa Baeza | AO22: =IF(E22="","",TRIM(IFERROR(LEFT(E22,FIND("(",E22)-1),E22))) | AP22: =IF(G22="","",TRIM(IFERROR(LEFT(G22,FIND("(",G22)-1),G22))) | AQ22: =IF(I22="","",TRIM(IFERROR(LEFT(I22,FIND("(",I22)-1),I22))) -> Alex Palacios | AR22: =IF(K22="","",TRIM(IFERROR(LEFT(K22,FIND("(",K22)-1),K22))) -> Edi Yunue Vega Bustamante | AS22: =IF(M22="","",TRIM(IFERROR(LEFT(M22,FIND("(",M22)-1),M22))) | AT22: =IF(O22="","",TRIM(IFERROR(LEFT(O22,FIND("(",O22)-1),O22))) | AU22: =IF(Q22="","",TRIM(IFERROR(LEFT(Q22,FIND("(",Q22)-1),Q22)))
A23: 9 | C23: Maria Herlinda Zavala | I23: Eduardo Leon | K23: Gilberto Diaz | T23: =IF(B23<>"",TRIM(IFERROR(LEFT(B23,FIND("(",B23)-1),B23)),T22) -> Desoje | U23: =IF(D23<>"",TRIM(IFERROR(LEFT(D23,FIND("(",D23)-1),D23)),U22) -> Packing | V23: =IF(F23<>"",TRIM(IFERROR(LEFT(F23,FIND("(",F23)-1),F23)),V22) | W23: =IF(H23<>"",TRIM(IFERROR(LEFT(H23,FIND("(",H23)-1),H23)),W22) -> Colgar | X23: =IF(J23<>"",TRIM(IFERROR(LEFT(J23,FIND("(",J23)-1),J23)),X22) -> Cortar | Y23: =IF(L23<>"",TRIM(IFERROR(LEFT(L23,FIND("(",L23)-1),L23)),Y22) -> Regar | Z23: =IF(N23<>"",TRIM(IFERROR(LEFT(N23,FIND("(",N23)-1),N23)),Z22) -> Fresh frozen | AA23: =IF(P23<>"",TRIM(IFERROR(LEFT(P23,FIND("(",P23)-1),P23)),AA22) | AD23: =IF(C23="","",IF(T23="","(sin responsabilidad)",T23)) -> Desoje | AE23: =IF(E23="","",IF(U23="","(sin responsabilidad)",U23)) | AF23: =IF(G23="","",IF(V23="","(sin responsabilidad)",V23)) | AG23: =IF(I23="","",IF(W23="","(sin responsabilidad)",W23)) -> Colgar | AH23: =IF(K23="","",IF(X23="","(sin responsabilidad)",X23)) -> Cortar | AI23: =IF(M23="","",IF(Y23="","(sin responsabilidad)",Y23)) | AJ23: =IF(O23="","",IF(Z23="","(sin responsabilidad)",Z23)) | AK23: =IF(Q23="","",IF(AA23="","(sin responsabilidad)",AA23)) | AN23: =IF(C23="","",TRIM(IFERROR(LEFT(C23,FIND("(",C23)-1),C23))) -> Maria Herlinda Zavala | AO23: =IF(E23="","",TRIM(IFERROR(LEFT(E23,FIND("(",E23)-1),E23))) | AP23: =IF(G23="","",TRIM(IFERROR(LEFT(G23,FIND("(",G23)-1),G23))) | AQ23: =IF(I23="","",TRIM(IFERROR(LEFT(I23,FIND("(",I23)-1),I23))) -> Eduardo Leon | AR23: =IF(K23="","",TRIM(IFERROR(LEFT(K23,FIND("(",K23)-1),K23))) -> Gilberto Diaz | AS23: =IF(M23="","",TRIM(IFERROR(LEFT(M23,FIND("(",M23)-1),M23))) | AT23: =IF(O23="","",TRIM(IFERROR(LEFT(O23,FIND("(",O23)-1),O23))) | AU23: =IF(Q23="","",TRIM(IFERROR(LEFT(Q23,FIND("(",Q23)-1),Q23)))
A24: 10 | C24: Raquel Garcia | H24: Cuartos | I24: Kevin Sicairos | J24: Chofer | K24: Jorge Rojas (sale 5am) | T24: =IF(B24<>"",TRIM(IFERROR(LEFT(B24,FIND("(",B24)-1),B24)),T23) -> Desoje | U24: =IF(D24<>"",TRIM(IFERROR(LEFT(D24,FIND("(",D24)-1),D24)),U23) -> Packing | V24: =IF(F24<>"",TRIM(IFERROR(LEFT(F24,FIND("(",F24)-1),F24)),V23) | W24: =IF(H24<>"",TRIM(IFERROR(LEFT(H24,FIND("(",H24)-1),H24)),W23) -> Cuartos | X24: =IF(J24<>"",TRIM(IFERROR(LEFT(J24,FIND("(",J24)-1),J24)),X23) -> Chofer | Y24: =IF(L24<>"",TRIM(IFERROR(LEFT(L24,FIND("(",L24)-1),L24)),Y23) -> Regar | Z24: =IF(N24<>"",TRIM(IFERROR(LEFT(N24,FIND("(",N24)-1),N24)),Z23) -> Fresh frozen | AA24: =IF(P24<>"",TRIM(IFERROR(LEFT(P24,FIND("(",P24)-1),P24)),AA23) | AD24: =IF(C24="","",IF(T24="","(sin responsabilidad)",T24)) -> Desoje | AE24: =IF(E24="","",IF(U24="","(sin responsabilidad)",U24)) | AF24: =IF(G24="","",IF(V24="","(sin responsabilidad)",V24)) | AG24: =IF(I24="","",IF(W24="","(sin responsabilidad)",W24)) -> Cuartos | AH24: =IF(K24="","",IF(X24="","(sin responsabilidad)",X24)) -> Chofer | AI24: =IF(M24="","",IF(Y24="","(sin responsabilidad)",Y24)) | AJ24: =IF(O24="","",IF(Z24="","(sin responsabilidad)",Z24)) | AK24: =IF(Q24="","",IF(AA24="","(sin responsabilidad)",AA24)) | AN24: =IF(C24="","",TRIM(IFERROR(LEFT(C24,FIND("(",C24)-1),C24))) -> Raquel Garcia | AO24: =IF(E24="","",TRIM(IFERROR(LEFT(E24,FIND("(",E24)-1),E24))) | AP24: =IF(G24="","",TRIM(IFERROR(LEFT(G24,FIND("(",G24)-1),G24))) | AQ24: =IF(I24="","",TRIM(IFERROR(LEFT(I24,FIND("(",I24)-1),I24))) -> Kevin Sicairos | AR24: =IF(K24="","",TRIM(IFERROR(LEFT(K24,FIND("(",K24)-1),K24))) -> Jorge Rojas | AS24: =IF(M24="","",TRIM(IFERROR(LEFT(M24,FIND("(",M24)-1),M24))) | AT24: =IF(O24="","",TRIM(IFERROR(LEFT(O24,FIND("(",O24)-1),O24))) | AU24: =IF(Q24="","",TRIM(IFERROR(LEFT(Q24,FIND("(",Q24)-1),Q24)))
A25: 11 | C25: Alma Garcia | K25: Ernesto Daniel Sicairos (sale 4am) | T25: =IF(B25<>"",TRIM(IFERROR(LEFT(B25,FIND("(",B25)-1),B25)),T24) -> Desoje | U25: =IF(D25<>"",TRIM(IFERROR(LEFT(D25,FIND("(",D25)-1),D25)),U24) -> Packing | V25: =IF(F25<>"",TRIM(IFERROR(LEFT(F25,FIND("(",F25)-1),F25)),V24) | W25: =IF(H25<>"",TRIM(IFERROR(LEFT(H25,FIND("(",H25)-1),H25)),W24) -> Cuartos | X25: =IF(J25<>"",TRIM(IFERROR(LEFT(J25,FIND("(",J25)-1),J25)),X24) -> Chofer | Y25: =IF(L25<>"",TRIM(IFERROR(LEFT(L25,FIND("(",L25)-1),L25)),Y24) -> Regar | Z25: =IF(N25<>"",TRIM(IFERROR(LEFT(N25,FIND("(",N25)-1),N25)),Z24) -> Fresh frozen | AA25: =IF(P25<>"",TRIM(IFERROR(LEFT(P25,FIND("(",P25)-1),P25)),AA24) | AD25: =IF(C25="","",IF(T25="","(sin responsabilidad)",T25)) -> Desoje | AE25: =IF(E25="","",IF(U25="","(sin responsabilidad)",U25)) | AF25: =IF(G25="","",IF(V25="","(sin responsabilidad)",V25)) | AG25: =IF(I25="","",IF(W25="","(sin responsabilidad)",W25)) | AH25: =IF(K25="","",IF(X25="","(sin responsabilidad)",X25)) -> Chofer | AI25: =IF(M25="","",IF(Y25="","(sin responsabilidad)",Y25)) | AJ25: =IF(O25="","",IF(Z25="","(sin responsabilidad)",Z25)) | AK25: =IF(Q25="","",IF(AA25="","(sin responsabilidad)",AA25)) | AN25: =IF(C25="","",TRIM(IFERROR(LEFT(C25,FIND("(",C25)-1),C25))) -> Alma Garcia | AO25: =IF(E25="","",TRIM(IFERROR(LEFT(E25,FIND("(",E25)-1),E25))) | AP25: =IF(G25="","",TRIM(IFERROR(LEFT(G25,FIND("(",G25)-1),G25))) | AQ25: =IF(I25="","",TRIM(IFERROR(LEFT(I25,FIND("(",I25)-1),I25))) | AR25: =IF(K25="","",TRIM(IFERROR(LEFT(K25,FIND("(",K25)-1),K25))) -> Ernesto Daniel Sicairos | AS25: =IF(M25="","",TRIM(IFERROR(LEFT(M25,FIND("(",M25)-1),M25))) | AT25: =IF(O25="","",TRIM(IFERROR(LEFT(O25,FIND("(",O25)-1),O25))) | AU25: =IF(Q25="","",TRIM(IFERROR(LEFT(Q25,FIND("(",Q25)-1),Q25)))
A26: 12 | C26: Yuliana Rivas Garcia | K26: Antonio Rivas (sale 3am) | T26: =IF(B26<>"",TRIM(IFERROR(LEFT(B26,FIND("(",B26)-1),B26)),T25) -> Desoje | U26: =IF(D26<>"",TRIM(IFERROR(LEFT(D26,FIND("(",D26)-1),D26)),U25) -> Packing | V26: =IF(F26<>"",TRIM(IFERROR(LEFT(F26,FIND("(",F26)-1),F26)),V25) | W26: =IF(H26<>"",TRIM(IFERROR(LEFT(H26,FIND("(",H26)-1),H26)),W25) -> Cuartos | X26: =IF(J26<>"",TRIM(IFERROR(LEFT(J26,FIND("(",J26)-1),J26)),X25) -> Chofer | Y26: =IF(L26<>"",TRIM(IFERROR(LEFT(L26,FIND("(",L26)-1),L26)),Y25) -> Regar | Z26: =IF(N26<>"",TRIM(IFERROR(LEFT(N26,FIND("(",N26)-1),N26)),Z25) -> Fresh frozen | AA26: =IF(P26<>"",TRIM(IFERROR(LEFT(P26,FIND("(",P26)-1),P26)),AA25) | AD26: =IF(C26="","",IF(T26="","(sin responsabilidad)",T26)) -> Desoje | AE26: =IF(E26="","",IF(U26="","(sin responsabilidad)",U26)) | AF26: =IF(G26="","",IF(V26="","(sin responsabilidad)",V26)) | AG26: =IF(I26="","",IF(W26="","(sin responsabilidad)",W26)) | AH26: =IF(K26="","",IF(X26="","(sin responsabilidad)",X26)) -> Chofer | AI26: =IF(M26="","",IF(Y26="","(sin responsabilidad)",Y26)) | AJ26: =IF(O26="","",IF(Z26="","(sin responsabilidad)",Z26)) | AK26: =IF(Q26="","",IF(AA26="","(sin responsabilidad)",AA26)) | AN26: =IF(C26="","",TRIM(IFERROR(LEFT(C26,FIND("(",C26)-1),C26))) -> Yuliana Rivas Garcia | AO26: =IF(E26="","",TRIM(IFERROR(LEFT(E26,FIND("(",E26)-1),E26))) | AP26: =IF(G26="","",TRIM(IFERROR(LEFT(G26,FIND("(",G26)-1),G26))) | AQ26: =IF(I26="","",TRIM(IFERROR(LEFT(I26,FIND("(",I26)-1),I26))) | AR26: =IF(K26="","",TRIM(IFERROR(LEFT(K26,FIND("(",K26)-1),K26))) -> Antonio Rivas | AS26: =IF(M26="","",TRIM(IFERROR(LEFT(M26,FIND("(",M26)-1),M26))) | AT26: =IF(O26="","",TRIM(IFERROR(LEFT(O26,FIND("(",O26)-1),O26))) | AU26: =IF(Q26="","",TRIM(IFERROR(LEFT(Q26,FIND("(",Q26)-1),Q26)))
A27: 13 | C27: Sr. Juan Ninche | K27: Antonio Sonato (sale 6am) | T27: =IF(B27<>"",TRIM(IFERROR(LEFT(B27,FIND("(",B27)-1),B27)),T26) -> Desoje | U27: =IF(D27<>"",TRIM(IFERROR(LEFT(D27,FIND("(",D27)-1),D27)),U26) -> Packing | V27: =IF(F27<>"",TRIM(IFERROR(LEFT(F27,FIND("(",F27)-1),F27)),V26) | W27: =IF(H27<>"",TRIM(IFERROR(LEFT(H27,FIND("(",H27)-1),H27)),W26) -> Cuartos | X27: =IF(J27<>"",TRIM(IFERROR(LEFT(J27,FIND("(",J27)-1),J27)),X26) -> Chofer | Y27: =IF(L27<>"",TRIM(IFERROR(LEFT(L27,FIND("(",L27)-1),L27)),Y26) -> Regar | Z27: =IF(N27<>"",TRIM(IFERROR(LEFT(N27,FIND("(",N27)-1),N27)),Z26) -> Fresh frozen | AA27: =IF(P27<>"",TRIM(IFERROR(LEFT(P27,FIND("(",P27)-1),P27)),AA26) | AD27: =IF(C27="","",IF(T27="","(sin responsabilidad)",T27)) -> Desoje | AE27: =IF(E27="","",IF(U27="","(sin responsabilidad)",U27)) | AF27: =IF(G27="","",IF(V27="","(sin responsabilidad)",V27)) | AG27: =IF(I27="","",IF(W27="","(sin responsabilidad)",W27)) | AH27: =IF(K27="","",IF(X27="","(sin responsabilidad)",X27)) -> Chofer | AI27: =IF(M27="","",IF(Y27="","(sin responsabilidad)",Y27)) | AJ27: =IF(O27="","",IF(Z27="","(sin responsabilidad)",Z27)) | AK27: =IF(Q27="","",IF(AA27="","(sin responsabilidad)",AA27)) | AN27: =IF(C27="","",TRIM(IFERROR(LEFT(C27,FIND("(",C27)-1),C27))) -> Sr. Juan Ninche | AO27: =IF(E27="","",TRIM(IFERROR(LEFT(E27,FIND("(",E27)-1),E27))) | AP27: =IF(G27="","",TRIM(IFERROR(LEFT(G27,FIND("(",G27)-1),G27))) | AQ27: =IF(I27="","",TRIM(IFERROR(LEFT(I27,FIND("(",I27)-1),I27))) | AR27: =IF(K27="","",TRIM(IFERROR(LEFT(K27,FIND("(",K27)-1),K27))) -> Antonio Sonato | AS27: =IF(M27="","",TRIM(IFERROR(LEFT(M27,FIND("(",M27)-1),M27))) | AT27: =IF(O27="","",TRIM(IFERROR(LEFT(O27,FIND("(",O27)-1),O27))) | AU27: =IF(Q27="","",TRIM(IFERROR(LEFT(Q27,FIND("(",Q27)-1),Q27)))
A28: 14 | C28: Flor Sierra | T28: =IF(B28<>"",TRIM(IFERROR(LEFT(B28,FIND("(",B28)-1),B28)),T27) -> Desoje | U28: =IF(D28<>"",TRIM(IFERROR(LEFT(D28,FIND("(",D28)-1),D28)),U27) -> Packing | V28: =IF(F28<>"",TRIM(IFERROR(LEFT(F28,FIND("(",F28)-1),F28)),V27) | W28: =IF(H28<>"",TRIM(IFERROR(LEFT(H28,FIND("(",H28)-1),H28)),W27) -> Cuartos | X28: =IF(J28<>"",TRIM(IFERROR(LEFT(J28,FIND("(",J28)-1),J28)),X27) -> Chofer | Y28: =IF(L28<>"",TRIM(IFERROR(LEFT(L28,FIND("(",L28)-1),L28)),Y27) -> Regar | Z28: =IF(N28<>"",TRIM(IFERROR(LEFT(N28,FIND("(",N28)-1),N28)),Z27) -> Fresh frozen | AA28: =IF(P28<>"",TRIM(IFERROR(LEFT(P28,FIND("(",P28)-1),P28)),AA27) | AD28: =IF(C28="","",IF(T28="","(sin responsabilidad)",T28)) -> Desoje | AE28: =IF(E28="","",IF(U28="","(sin responsabilidad)",U28)) | AF28: =IF(G28="","",IF(V28="","(sin responsabilidad)",V28)) | AG28: =IF(I28="","",IF(W28="","(sin responsabilidad)",W28)) | AH28: =IF(K28="","",IF(X28="","(sin responsabilidad)",X28)) | AI28: =IF(M28="","",IF(Y28="","(sin responsabilidad)",Y28)) | AJ28: =IF(O28="","",IF(Z28="","(sin responsabilidad)",Z28)) | AK28: =IF(Q28="","",IF(AA28="","(sin responsabilidad)",AA28)) | AN28: =IF(C28="","",TRIM(IFERROR(LEFT(C28,FIND("(",C28)-1),C28))) -> Flor Sierra | AO28: =IF(E28="","",TRIM(IFERROR(LEFT(E28,FIND("(",E28)-1),E28))) | AP28: =IF(G28="","",TRIM(IFERROR(LEFT(G28,FIND("(",G28)-1),G28))) | AQ28: =IF(I28="","",TRIM(IFERROR(LEFT(I28,FIND("(",I28)-1),I28))) | AR28: =IF(K28="","",TRIM(IFERROR(LEFT(K28,FIND("(",K28)-1),K28))) | AS28: =IF(M28="","",TRIM(IFERROR(LEFT(M28,FIND("(",M28)-1),M28))) | AT28: =IF(O28="","",TRIM(IFERROR(LEFT(O28,FIND("(",O28)-1),O28))) | AU28: =IF(Q28="","",TRIM(IFERROR(LEFT(Q28,FIND("(",Q28)-1),Q28)))
A29: 15 | C29: Maria Elena Mendoza | T29: =IF(B29<>"",TRIM(IFERROR(LEFT(B29,FIND("(",B29)-1),B29)),T28) -> Desoje | U29: =IF(D29<>"",TRIM(IFERROR(LEFT(D29,FIND("(",D29)-1),D29)),U28) -> Packing | V29: =IF(F29<>"",TRIM(IFERROR(LEFT(F29,FIND("(",F29)-1),F29)),V28) | W29: =IF(H29<>"",TRIM(IFERROR(LEFT(H29,FIND("(",H29)-1),H29)),W28) -> Cuartos | X29: =IF(J29<>"",TRIM(IFERROR(LEFT(J29,FIND("(",J29)-1),J29)),X28) -> Chofer | Y29: =IF(L29<>"",TRIM(IFERROR(LEFT(L29,FIND("(",L29)-1),L29)),Y28) -> Regar | Z29: =IF(N29<>"",TRIM(IFERROR(LEFT(N29,FIND("(",N29)-1),N29)),Z28) -> Fresh frozen | AA29: =IF(P29<>"",TRIM(IFERROR(LEFT(P29,FIND("(",P29)-1),P29)),AA28) | AD29: =IF(C29="","",IF(T29="","(sin responsabilidad)",T29)) -> Desoje | AE29: =IF(E29="","",IF(U29="","(sin responsabilidad)",U29)) | AF29: =IF(G29="","",IF(V29="","(sin responsabilidad)",V29)) | AG29: =IF(I29="","",IF(W29="","(sin responsabilidad)",W29)) | AH29: =IF(K29="","",IF(X29="","(sin responsabilidad)",X29)) | AI29: =IF(M29="","",IF(Y29="","(sin responsabilidad)",Y29)) | AJ29: =IF(O29="","",IF(Z29="","(sin responsabilidad)",Z29)) | AK29: =IF(Q29="","",IF(AA29="","(sin responsabilidad)",AA29)) | AN29: =IF(C29="","",TRIM(IFERROR(LEFT(C29,FIND("(",C29)-1),C29))) -> Maria Elena Mendoza | AO29: =IF(E29="","",TRIM(IFERROR(LEFT(E29,FIND("(",E29)-1),E29))) | AP29: =IF(G29="","",TRIM(IFERROR(LEFT(G29,FIND("(",G29)-1),G29))) | AQ29: =IF(I29="","",TRIM(IFERROR(LEFT(I29,FIND("(",I29)-1),I29))) | AR29: =IF(K29="","",TRIM(IFERROR(LEFT(K29,FIND("(",K29)-1),K29))) | AS29: =IF(M29="","",TRIM(IFERROR(LEFT(M29,FIND("(",M29)-1),M29))) | AT29: =IF(O29="","",TRIM(IFERROR(LEFT(O29,FIND("(",O29)-1),O29))) | AU29: =IF(Q29="","",TRIM(IFERROR(LEFT(Q29,FIND("(",Q29)-1),Q29)))
A30: 16 | C30: Rosa Navarro | T30: =IF(B30<>"",TRIM(IFERROR(LEFT(B30,FIND("(",B30)-1),B30)),T29) -> Desoje | U30: =IF(D30<>"",TRIM(IFERROR(LEFT(D30,FIND("(",D30)-1),D30)),U29) -> Packing | V30: =IF(F30<>"",TRIM(IFERROR(LEFT(F30,FIND("(",F30)-1),F30)),V29) | W30: =IF(H30<>"",TRIM(IFERROR(LEFT(H30,FIND("(",H30)-1),H30)),W29) -> Cuartos | X30: =IF(J30<>"",TRIM(IFERROR(LEFT(J30,FIND("(",J30)-1),J30)),X29) -> Chofer | Y30: =IF(L30<>"",TRIM(IFERROR(LEFT(L30,FIND("(",L30)-1),L30)),Y29) -> Regar | Z30: =IF(N30<>"",TRIM(IFERROR(LEFT(N30,FIND("(",N30)-1),N30)),Z29) -> Fresh frozen | AA30: =IF(P30<>"",TRIM(IFERROR(LEFT(P30,FIND("(",P30)-1),P30)),AA29) | AD30: =IF(C30="","",IF(T30="","(sin responsabilidad)",T30)) -> Desoje | AE30: =IF(E30="","",IF(U30="","(sin responsabilidad)",U30)) | AF30: =IF(G30="","",IF(V30="","(sin responsabilidad)",V30)) | AG30: =IF(I30="","",IF(W30="","(sin responsabilidad)",W30)) | AH30: =IF(K30="","",IF(X30="","(sin responsabilidad)",X30)) | AI30: =IF(M30="","",IF(Y30="","(sin responsabilidad)",Y30)) | AJ30: =IF(O30="","",IF(Z30="","(sin responsabilidad)",Z30)) | AK30: =IF(Q30="","",IF(AA30="","(sin responsabilidad)",AA30)) | AN30: =IF(C30="","",TRIM(IFERROR(LEFT(C30,FIND("(",C30)-1),C30))) -> Rosa Navarro | AO30: =IF(E30="","",TRIM(IFERROR(LEFT(E30,FIND("(",E30)-1),E30))) | AP30: =IF(G30="","",TRIM(IFERROR(LEFT(G30,FIND("(",G30)-1),G30))) | AQ30: =IF(I30="","",TRIM(IFERROR(LEFT(I30,FIND("(",I30)-1),I30))) | AR30: =IF(K30="","",TRIM(IFERROR(LEFT(K30,FIND("(",K30)-1),K30))) | AS30: =IF(M30="","",TRIM(IFERROR(LEFT(M30,FIND("(",M30)-1),M30))) | AT30: =IF(O30="","",TRIM(IFERROR(LEFT(O30,FIND("(",O30)-1),O30))) | AU30: =IF(Q30="","",TRIM(IFERROR(LEFT(Q30,FIND("(",Q30)-1),Q30)))
A31: 17 | C31: Brenda Olivas | T31: =IF(B31<>"",TRIM(IFERROR(LEFT(B31,FIND("(",B31)-1),B31)),T30) -> Desoje | U31: =IF(D31<>"",TRIM(IFERROR(LEFT(D31,FIND("(",D31)-1),D31)),U30) -> Packing | V31: =IF(F31<>"",TRIM(IFERROR(LEFT(F31,FIND("(",F31)-1),F31)),V30) | W31: =IF(H31<>"",TRIM(IFERROR(LEFT(H31,FIND("(",H31)-1),H31)),W30) -> Cuartos | X31: =IF(J31<>"",TRIM(IFERROR(LEFT(J31,FIND("(",J31)-1),J31)),X30) -> Chofer | Y31: =IF(L31<>"",TRIM(IFERROR(LEFT(L31,FIND("(",L31)-1),L31)),Y30) -> Regar | Z31: =IF(N31<>"",TRIM(IFERROR(LEFT(N31,FIND("(",N31)-1),N31)),Z30) -> Fresh frozen | AA31: =IF(P31<>"",TRIM(IFERROR(LEFT(P31,FIND("(",P31)-1),P31)),AA30) | AD31: =IF(C31="","",IF(T31="","(sin responsabilidad)",T31)) -> Desoje | AE31: =IF(E31="","",IF(U31="","(sin responsabilidad)",U31)) | AF31: =IF(G31="","",IF(V31="","(sin responsabilidad)",V31)) | AG31: =IF(I31="","",IF(W31="","(sin responsabilidad)",W31)) | AH31: =IF(K31="","",IF(X31="","(sin responsabilidad)",X31)) | AI31: =IF(M31="","",IF(Y31="","(sin responsabilidad)",Y31)) | AJ31: =IF(O31="","",IF(Z31="","(sin responsabilidad)",Z31)) | AK31: =IF(Q31="","",IF(AA31="","(sin responsabilidad)",AA31)) | AN31: =IF(C31="","",TRIM(IFERROR(LEFT(C31,FIND("(",C31)-1),C31))) -> Brenda Olivas | AO31: =IF(E31="","",TRIM(IFERROR(LEFT(E31,FIND("(",E31)-1),E31))) | AP31: =IF(G31="","",TRIM(IFERROR(LEFT(G31,FIND("(",G31)-1),G31))) | AQ31: =IF(I31="","",TRIM(IFERROR(LEFT(I31,FIND("(",I31)-1),I31))) | AR31: =IF(K31="","",TRIM(IFERROR(LEFT(K31,FIND("(",K31)-1),K31))) | AS31: =IF(M31="","",TRIM(IFERROR(LEFT(M31,FIND("(",M31)-1),M31))) | AT31: =IF(O31="","",TRIM(IFERROR(LEFT(O31,FIND("(",O31)-1),O31))) | AU31: =IF(Q31="","",TRIM(IFERROR(LEFT(Q31,FIND("(",Q31)-1),Q31)))
